[2024-07-30T18:08:57.745+0000] {taskinstance.py:1979} INFO - Dependencies all met for dep_context=non-requeueable deps ti=<TaskInstance: churn_prediction_etl.churn_prediction manual__2024-07-30T18:08:39.456933+00:00 [queued]>
[2024-07-30T18:08:57.753+0000] {taskinstance.py:1979} INFO - Dependencies all met for dep_context=requeueable deps ti=<TaskInstance: churn_prediction_etl.churn_prediction manual__2024-07-30T18:08:39.456933+00:00 [queued]>
[2024-07-30T18:08:57.753+0000] {taskinstance.py:2193} INFO - Starting attempt 3 of 3
[2024-07-30T18:08:57.765+0000] {taskinstance.py:2217} INFO - Executing <Task(ClickHouseOperatorExtended): churn_prediction> on 2024-07-30 18:08:39.456933+00:00
[2024-07-30T18:08:57.770+0000] {standard_task_runner.py:60} INFO - Started process 86 to run task
[2024-07-30T18:08:57.774+0000] {standard_task_runner.py:87} INFO - Running: ['***', 'tasks', 'run', 'churn_prediction_etl', 'churn_prediction', 'manual__2024-07-30T18:08:39.456933+00:00', '--job-id', '33', '--raw', '--subdir', 'DAGS_FOLDER/churn_prediction_etl.py', '--cfg-path', '/tmp/tmplsk300cn']
[2024-07-30T18:08:57.776+0000] {standard_task_runner.py:88} INFO - Job 33: Subtask churn_prediction
[2024-07-30T18:08:57.816+0000] {task_command.py:423} INFO - Running <TaskInstance: churn_prediction_etl.churn_prediction manual__2024-07-30T18:08:39.456933+00:00 [running]> on host 16c05e324510
[2024-07-30T18:08:57.857+0000] {abstractoperator.py:707} ERROR - Exception rendering Jinja template for task 'churn_prediction', field '_sql'. Template: 'churn_prediction.sql'
Traceback (most recent call last):
  File "/home/airflow/.local/lib/python3.8/site-packages/airflow/models/abstractoperator.py", line 699, in _do_render_template_fields
    rendered_content = self.render_template(
  File "/home/airflow/.local/lib/python3.8/site-packages/airflow/template/templater.py", line 171, in render_template
    template = jinja_env.get_template(value)
  File "/home/airflow/.local/lib/python3.8/site-packages/jinja2/environment.py", line 1010, in get_template
    return self._load_template(name, globals)
  File "/home/airflow/.local/lib/python3.8/site-packages/jinja2/environment.py", line 969, in _load_template
    template = self.loader.load(self, name, self.make_globals(globals))
  File "/home/airflow/.local/lib/python3.8/site-packages/jinja2/loaders.py", line 125, in load
    source, filename, uptodate = self.get_source(environment, name)
  File "/home/airflow/.local/lib/python3.8/site-packages/jinja2/loaders.py", line 204, in get_source
    raise TemplateNotFound(template)
jinja2.exceptions.TemplateNotFound: churn_prediction.sql
[2024-07-30T18:08:57.859+0000] {taskinstance.py:2731} ERROR - Task failed with exception
Traceback (most recent call last):
  File "/home/airflow/.local/lib/python3.8/site-packages/airflow/models/taskinstance.py", line 2360, in _run_raw_task
    self._execute_task_with_callbacks(context, test_mode, session=session)
  File "/home/airflow/.local/lib/python3.8/site-packages/airflow/models/taskinstance.py", line 2498, in _execute_task_with_callbacks
    task_orig = self.render_templates(context=context)
  File "/home/airflow/.local/lib/python3.8/site-packages/airflow/models/taskinstance.py", line 2910, in render_templates
    original_task.render_template_fields(context)
  File "/home/airflow/.local/lib/python3.8/site-packages/airflow/models/baseoperator.py", line 1241, in render_template_fields
    self._do_render_template_fields(self, self.template_fields, context, jinja_env, set())
  File "/home/airflow/.local/lib/python3.8/site-packages/airflow/utils/session.py", line 79, in wrapper
    return func(*args, session=session, **kwargs)
  File "/home/airflow/.local/lib/python3.8/site-packages/airflow/models/abstractoperator.py", line 699, in _do_render_template_fields
    rendered_content = self.render_template(
  File "/home/airflow/.local/lib/python3.8/site-packages/airflow/template/templater.py", line 171, in render_template
    template = jinja_env.get_template(value)
  File "/home/airflow/.local/lib/python3.8/site-packages/jinja2/environment.py", line 1010, in get_template
    return self._load_template(name, globals)
  File "/home/airflow/.local/lib/python3.8/site-packages/jinja2/environment.py", line 969, in _load_template
    template = self.loader.load(self, name, self.make_globals(globals))
  File "/home/airflow/.local/lib/python3.8/site-packages/jinja2/loaders.py", line 125, in load
    source, filename, uptodate = self.get_source(environment, name)
  File "/home/airflow/.local/lib/python3.8/site-packages/jinja2/loaders.py", line 204, in get_source
    raise TemplateNotFound(template)
jinja2.exceptions.TemplateNotFound: churn_prediction.sql
[2024-07-30T18:08:57.865+0000] {taskinstance.py:1149} INFO - Marking task as FAILED. dag_id=churn_prediction_etl, task_id=churn_prediction, execution_date=20240730T180839, start_date=20240730T180857, end_date=20240730T180857
[2024-07-30T18:08:57.876+0000] {standard_task_runner.py:107} ERROR - Failed to execute job 33 for task churn_prediction (churn_prediction.sql; 86)
[2024-07-30T18:08:57.905+0000] {local_task_job_runner.py:234} INFO - Task exited with return code 1
[2024-07-30T18:08:57.925+0000] {taskinstance.py:3312} INFO - 0 downstream tasks scheduled from follow-on schedule check
